Workbook

Sheet Sheet2
C1: # | D1: Week | E1: Day | F1: - | G1: L | H1: M | I1: C | J1: L | K1: - | L1: - | M1: -
C2: 1 | D2: 1 | E2: 1 | G2: 1 | H2: 1 | I2: 1 | J2: 1 | K2: Foundation – Your First Agent Call | L2: Plan and Prepare to Develop AI Solutions on Azure | M2: What Is an AI Agent? | AA2: Type | AB2: Code | AC2: Module | AD2: Name
C3: 1 | D3: 1 | E3: 1 | G3: 1 | H3: 1 | I3: 2 | J3: 1 | K3: Foundation – Your First Agent Call | L3: Plan and Prepare to Develop AI Solutions on Azure | M3: Unit 1 Code Walkthrough: Deploying your first Agent
C4: 1 | D4: 1 | E4: 1 | G4: 1 | H4: 1 | I4: 3 | J4: 1 | K4: Foundation – Your First Agent Call | L4: Plan and Prepare to Develop AI Solutions on Azure | M4: Microsoft Foundry – The Agent Development Platform
C5: 2 | D5: 1 | E5: 2 | G5: 1 | H5: 6 | I5: 5 | J5: 2 | K5: Content Safety – Input and Output Filtering | L5: Implement a Responsible Generative AI Solution in Microsoft Foundry | M5: Responsible AI & Safety for Agents | AA5: MS Learning Path | AB5: LP1 | AD5: Develop Generative AI Apps in Azure
C6: 3 | D6: 1 | E6: 3 | G6: 1 | H6: 2 | I6: 6 | J6: 4 | K6: Model Selection – LLM vs SLM Routing | L6: Select, Deploy, and Evaluate Microsoft Foundry Models | M6: Model Selection – LLMs vs. SLMs for Agent Tasks | AA6: MS Module | AB6: LP1 | AC6: M1 | AD6: Plan and Prepare to Develop AI Solutions on Azure
C7: 4 | D7: 1 | E7: 4 | G7: 1 | H7: 2 | I7: 16 | J7: 5 | K7: LLM Model Parameters (Temperature, etc.) | L7: Select, Deploy, and Evaluate Microsoft Foundry Models | M7: Performance Evaluation – Metrics That Matter | AA7: MS Module | AB7: LP1 | AC7: M2 | AD7: Select, Deploy, and Evaluate Microsoft Foundry Models
C8: 5 | D8: 1 | E8: 5 | G8: 1 | H8: 3 | I8: 9 | J8: 3 | K8: System Instructions – Dynamic Prompt Construction | L8: Develop a Generative AI Chat App with Microsoft Foundry | M8: Context Management – System Instructions | AA8: MS Module | AB8: LP1 | AC8: M3 | AD8: Develop a Generative AI Chat App with Microsoft Foundry
C9: 6 | D9: 1 | E9: 6 | G9: 1 | H9: 5 | I9: 20 | L9: Optimize Generative AI Model Performance with Microsoft Foundry | M9: System Instructions – Programmatic Prompt Construction | AA9: MS Module | AB9: LP1 | AC9: M4 | AD9: Develop Generative AI Apps That Use Tools
C10: 7 | D10: 1 | E10: 7 | AA10: MS Module | AB10: LP1 | AC10: M5 | AD10: Optimize Generative AI Model Performance with Microsoft Foundry
C11: 8 | D11: 2 | E11: 1 | G11: 1 | H11: 5 | I11: 7 | J11: 6 | K11: Azure AI Search (Part 1) – Basic Search and Retrieval | L11: Optimize Generative AI Model Performance with Microsoft Foundry | M11: Agentic RAG – Dynamic Retrieval for Agents | AA11: MS Module | AB11: LP1 | AC11: M6 | AD11: Implement a Responsible Generative AI Solution in Microsoft Foundry
C12: 9 | D12: 2 | E12: 2 | G12: 1 | H12: 5 | I12: 8 | J12: 7 | K12: Azure AI Search (Part 2) – Vector Search and Semantic Ranking | L12: Optimize Generative AI Model Performance with Microsoft Foundry | M12: Advanced Grounding – Fabric & Cosmos DB | AA12: MS Learning Path | AB12: LP2 | AD12: Develop AI Agents on Azure
C13: 10 | D13: 2 | E13: 3 | G13: 4 | H13: 8 | J13: 8 | K13: Azure AI Search (Part 3) – Agentic RAG | L13: Create a Knowledge Mining Solution with Azure AI Search | AA13: MS Module | AB13: LP2 | AC13: M1 | AD13: Develop AI Agents with Microsoft Foundry and Visual Studio Code
C14: 11 | D14: 2 | E14: 4 | G14: 1 | H14: 4 | I14: 11 | J14: 9 | K14: Tool Calling – REST API Integration | L14: Develop Generative AI Apps That Use Tools | M14: Tool Calling – Connecting Agents to APIs | AA14: MS Module | AB14: LP2 | AC14: M2 | AD14: Integrate Custom Tools into Your Agent
C15: 12 | D15: 2 | E15: 5 | G15: 2 | H15: 2 | L15: Integrate Custom Tools into Your Agent | AA15: MS Module | AB15: LP2 | AC15: M3 | AD15: Integrate MCP Tools with Azure AI Agents
C16: 13 | D16: 2 | E16: 6 | G16: 2 | H16: 3 | I16: 12 | J16: 10 | K16: Model Context Protocol (MCP) – Standardized Tool Connectivity | L16: Integrate MCP Tools with Azure AI Agents | M16: Model Context Protocol (MCP) – Standardized Tool Connectivity | AA16: MS Module | AB16: LP2 | AC16: M4 | AD16: Build Knowledge-Enhanced AI Agents with Foundry IQ
C17: 14 | D17: 2 | E17: 7 | AA17: MS Module | AB17: LP2 | AC17: M5 | AD17: Integrate Your Agent with Microsoft 365
C18: 15 | D18: 3 | E18: 1 | G18: 2 | H18: 1 | L18: Develop AI Agents with Microsoft Foundry and Visual Studio Code | AA18: MS Module | AB18: LP2 | AC18: M6 | AD18: Build Agent-Driven Workflows using Microsoft Foundry
C19: 16 | D19: 3 | E19: 2 | G19: 2 | H19: 1 | I19: 4 | J19: 19 | K19: Secure Secret Management with Azure Key Vault | L19: Develop AI Agents with Microsoft Foundry and Visual Studio Code | M19: Entra Agent ID – Agent Identity Deep Dive | AA19: MS Module | AB19: LP2 | AC19: M7 | AD19: Develop an AI Agent with Microsoft Agent Framework
C20: 17 | D20: 3 | E20: 3 | G20: 2 | H20: 4 | I20: 17 | J20: 15 | K20: Agent Memory – Short-Term Session Memory (Redis) | L20: Build Knowledge-Enhanced AI Agents with Foundry IQ | M20: Agent Memory – Short-Term and Long-Term State | AA20: MS Module | AB20: LP2 | AC20: M8 | AD20: Orchestrate a Multi-Agent Solution using the Microsoft Agent Framework
C21: 18 | D21: 3 | E21: 4 | J21: 16 | K21: Agent Memory – Long-Term User Memory (Cosmos DB) | AA21: MS Module | AB21: LP2 | AC21: M9 | AD21: Discover Azure AI Agents with A2A
C22: 19 | D22: 3 | E22: 5 | G22: 2 | H22: 6 | I22: 13 | J22: 13 | K22: Sequential vs Concurrent Agent Execution | L22: Build Agent-Driven Workflows using Microsoft Foundry | M22: Sequential vs. Concurrent Agent Execution | AA22: MS Learning Path | AB22: LP3 | AD22: Develop Natural Language Solutions in Azure
C23: 20 | D23: 3 | E23: 6 | G23: 2 | H23: 7 | I23: 10 | J23: 11 | K23: Multi-Agent – Handoff Pattern | L23: Develop an AI Agent with Microsoft Agent Framework | M23: Multi-Agent Orchestration – Microsoft Agent Framework | AA23: MS Module | AB23: LP3 | AC23: M1 | AD23: Analyze Text with Azure Language in Foundry Tools
C24: 21 | D24: 3 | E24: 7 | I24: 15 | J24: 14 | K24: OpenTelemetry Debugging | M24: Foundry Trace – OpenTelemetry Debugging | AA24: MS Module | AB24: LP3 | AC24: M2 | AD24: Develop a Text Analysis Agent with the Azure Language MCP Server
C25: 22 | D25: 4 | E25: 1 | G25: 2 | H25: 8 | I25: 14 | J25: 12 | K25: Multi-Agent – Manager (Magentic) Pattern | L25: Orchestrate a Multi-Agent Solution using the Microsoft Agent Framework | M25: Human-in-the-Loop (HITL) – Approval Gates | AA25: MS Module | AB25: LP3 | AC25: M3 | AD25: Develop a Speech-Capable Generative AI Application
C26: 23 | D26: 4 | E26: 2 | G26: 2 | H26: 9 | L26: Discover Azure AI Agents with A2A | AA26: MS Module | AB26: LP3 | AC26: M4 | AD26: Create Speech-Enabled Apps with Azure Speech in Microsoft Foundry Tools
C27: 24 | D27: 4 | E27: 3 | G27: 2 | H27: 5 | L27: Integrate Your Agent with Microsoft 365 | AA27: MS Module | AB27: LP3 | AC27: M5 | AD27: Develop a Speech Agent with the Azure Speech MCP Server
B28: 1 | C28: 25 | D28: 4 | E28: 4 | G28: 3 | H28: 1 | I28: 19 | J28: 18 | K28: Input Transformation – NLP Preprocessing | L28: Analyze Text with Azure Language in Foundry Tools | M28: Input Transformation – NLP Preprocessing for Agents | AA28: MS Module | AB28: LP3 | AC28: M6 | AD28: Develop an Azure Speech Voice Live Agent in Microsoft Foundry
B29: 2 | C29: 25 | D29: 4 | E29: 4 | G29: 3 | H29: 2 | I29: 19 | J29: 19 | K29: Secure Secret Management with Azure Key Vault | L29: Develop a Text Analysis Agent with the Azure Language MCP Server | M29: Input Transformation – NLP Preprocessing for Agents | AA29: MS Module | AB29: LP3 | AC29: M7 | AD29: Translate Text and Speech with Microsoft Foundry Tools
B30: 1 | C30: 26 | D30: 4 | E30: 5 | G30: 3 | H30: 3 | I30: 18 | L30: Develop a Speech-Capable Generative AI Application | M30: Multimodal Integration – Vision, Speech & Document Intelligence | AA30: MS Learning Path | AB30: LP4 | AD30: Extract Insights from Visual Data on Azure
B31: 2 | C31: 26 | D31: 4 | E31: 5 | G31: 3 | H31: 4 | I31: 18 | L31: Create Speech-Enabled Apps with Azure Speech in Microsoft Foundry Tools | M31: Multimodal Integration – Vision, Speech & Document Intelligence | AA31: MS Module | AB31: LP4 | AC31: M1 | AD31: Develop a Vision-Enabled Generative AI Application
B32: 1 | C32: 27 | D32: 4 | E32: 6 | G32: 3 | H32: 5 | L32: Develop a Speech Agent with the Azure Speech MCP Server | AA32: MS Module | AB32: LP4 | AC32: M2 | AD32: Generate Images with AI
B33: 2 | C33: 27 | D33: 4 | E33: 6 | G33: 3 | H33: 6 | L33: Develop an Azure Speech Voice Live Agent in Microsoft Foundry | AA33: MS Module | AB33: LP4 | AC33: M3 | AD33: Generate Videos with Microsoft Foundry
B34: 3 | C34: 27 | D34: 4 | E34: 6 | G34: 3 | H34: 7 | L34: Translate Text and Speech with Microsoft Foundry Tools | AA34: MS Module | AB34: LP4 | AC34: M4 | AD34: Analyze Images with Content Understanding
C35: 28 | D35: 4 | E35: 7 | AA35: MS Module | AB35: LP4 | AC35: M5 | AD35: Create a Multimodal Analysis Solution with Azure Content Understanding
B36: 1 | C36: 29 | D36: 5 | E36: 1 | G36: 4 | H36: 1 | J36: 17 | K36: Multimodal Integration – Vision, Speech, Document Intelligence | L36: Develop a Vision-Enabled Generative AI Application | AA36: MS Module | AB36: LP4 | AC36: M6 | AD36: Create an Azure Content Understanding Client Application
B37: 2 | C37: 29 | D37: 5 | E37: 1 | G37: 4 | H37: 2 | J37: 17 | K37: Multimodal Integration – Vision, Speech, Document Intelligence | L37: Generate Images with AI | AA37: MS Module | AB37: LP4 | AC37: M7 | AD37: Extract Data with Azure Document Intelligence
B38: 1 | C38: 30 | D38: 5 | E38: 2 | G38: 4 | H38: 3 | L38: Generate Videos with Microsoft Foundry | AA38: MS Module | AB38: LP4 | AC38: M8 | AD38: Create a Knowledge Mining Solution with Azure AI Search
B39: 2 | C39: 30 | D39: 5 | E39: 2 | G39: 4 | H39: 4 | L39: Analyze Images with Content Understanding | AA39: Udemy Concept | AB39: C1 | AD39: What Is an AI Agent?
B40: 1 | C40: 31 | D40: 5 | E40: 3 | G40: 4 | H40: 5 | L40: Create a Multimodal Analysis Solution with Azure Content Understanding | AA40: Udemy Concept | AB40: C2 | AD40: Unit 1 Code Walkthrough: Deploying your first Agent
...

Sheet Sheet2 (2)
C1: # | D1: Week | E1: Day | F1: - | G1: P | H1: M | I1: C | J1: L | K1: - | L1: - | M1: -
C2: 1 | D2: 1 | E2: 1 | G2: 1 | H2: 1 | I2: 1 | J2: 1 | K2: Foundation – Your First Agent Call | L2: Plan and Prepare to Develop AI Solutions on Azure | M2: What Is an AI Agent? | AA2: Type | AB2: Code | AC2: Module | AD2: Name
C3: 1 | D3: 1 | E3: 1 | G3: 1 | H3: 1 | I3: 2 | J3: 1 | K3: Foundation – Your First Agent Call | L3: Plan and Prepare to Develop AI Solutions on Azure | M3: Unit 1 Code Walkthrough: Deploying your first Agent
C4: 1 | D4: 1 | E4: 1 | G4: 1 | H4: 1 | I4: 3 | J4: 1 | K4: Foundation – Your First Agent Call | L4: Plan and Prepare to Develop AI Solutions on Azure | M4: Microsoft Foundry – The Agent Development Platform
C5: 3 | D5: 1 | E5: 3 | G5: 1 | H5: 2 | I5: 6 | J5: 4 | K5: Model Selection – LLM vs SLM Routing | L5: Select, Deploy, and Evaluate Microsoft Foundry Models | M5: Model Selection – LLMs vs. SLMs for Agent Tasks | AA5: MS Learning Path | AB5: LP1 | AD5: Develop Generative AI Apps in Azure
C6: 4 | D6: 1 | E6: 4 | G6: 1 | H6: 2 | I6: 16 | J6: 5 | K6: LLM Model Parameters (Temperature, etc.) | L6: Select, Deploy, and Evaluate Microsoft Foundry Models | M6: Performance Evaluation – Metrics That Matter | AA6: MS Module | AB6: LP1 | AC6: M1 | AD6: Plan and Prepare to Develop AI Solutions on Azure
C7: 5 | D7: 1 | E7: 5 | G7: 1 | H7: 3 | I7: 9 | J7: 3 | K7: System Instructions – Dynamic Prompt Construction | L7: Develop a Generative AI Chat App with Microsoft Foundry | M7: Context Management – System Instructions | AA7: MS Module | AB7: LP1 | AC7: M2 | AD7: Select, Deploy, and Evaluate Microsoft Foundry Models
C8: 11 | D8: 2 | E8: 4 | G8: 1 | H8: 4 | I8: 11 | J8: 9 | K8: Tool Calling – REST API Integration | L8: Develop Generative AI Apps That Use Tools | M8: Tool Calling – Connecting Agents to APIs | AA8: MS Module | AB8: LP1 | AC8: M3 | AD8: Develop a Generative AI Chat App with Microsoft Foundry
C9: 8 | D9: 2 | E9: 1 | G9: 1 | H9: 5 | I9: 7 | J9: 6 | K9: Azure AI Search (Part 1) – Basic Search and Retrieval | L9: Optimize Generative AI Model Performance with Microsoft Foundry | M9: Agentic RAG – Dynamic Retrieval for Agents | AA9: MS Module | AB9: LP1 | AC9: M4 | AD9: Develop Generative AI Apps That Use Tools
C10: 9 | D10: 2 | E10: 2 | G10: 1 | H10: 5 | I10: 8 | J10: 7 | K10: Azure AI Search (Part 2) – Vector Search and Semantic Ranking | L10: Optimize Generative AI Model Performance with Microsoft Foundry | M10: Advanced Grounding – Fabric & Cosmos DB | AA10: MS Module | AB10: LP1 | AC10: M5 | AD10: Optimize Generative AI Model Performance with Microsoft Foundry
C11: 6 | D11: 1 | E11: 6 | G11: 1 | H11: 5 | I11: 20 | L11: Optimize Generative AI Model Performance with Microsoft Foundry | M11: System Instructions – Programmatic Prompt Construction | AA11: MS Module | AB11: LP1 | AC11: M6 | AD11: Implement a Responsible Generative AI Solution in Microsoft Foundry
C12: 2 | D12: 1 | E12: 2 | G12: 1 | H12: 6 | I12: 5 | J12: 2 | K12: Content Safety – Input and Output Filtering | L12: Implement a Responsible Generative AI Solution in Microsoft Foundry | M12: Responsible AI & Safety for Agents | AA12: MS Learning Path | AB12: LP2 | AD12: Develop AI Agents on Azure
C14: 16 | D14: 3 | E14: 2 | G14: 2 | H14: 1 | I14: 4 | J14: 19 | K14: Secure Secret Management with Azure Key Vault | L14: Develop AI Agents with Microsoft Foundry and Visual Studio Code | M14: Entra Agent ID – Agent Identity Deep Dive | AA14: MS Module | AB14: LP2 | AC14: M1 | AD14: Develop AI Agents with Microsoft Foundry and Visual Studio Code
C15: 15 | D15: 3 | E15: 1 | G15: 2 | H15: 1 | L15: Develop AI Agents with Microsoft Foundry and Visual Studio Code | AA15: MS Module | AB15: LP2 | AC15: M2 | AD15: Integrate Custom Tools into Your Agent
C16: 12 | D16: 2 | E16: 5 | G16: 2 | H16: 2 | L16: Integrate Custom Tools into Your Agent | AA16: MS Module | AB16: LP2 | AC16: M3 | AD16: Integrate MCP Tools with Azure AI Agents
C17: 13 | D17: 2 | E17: 6 | G17: 2 | H17: 3 | I17: 12 | J17: 10 | K17: Model Context Protocol (MCP) – Standardized Tool Connectivity | L17: Integrate MCP Tools with Azure AI Agents | M17: Model Context Protocol (MCP) – Standardized Tool Connectivity | AA17: MS Module | AB17: LP2 | AC17: M4 | AD17: Build Knowledge-Enhanced AI Agents with Foundry IQ
C18: 17 | D18: 3 | E18: 3 | G18: 2 | H18: 4 | I18: 17 | J18: 15 | K18: Agent Memory – Short-Term Session Memory (Redis) | L18: Build Knowledge-Enhanced AI Agents with Foundry IQ | M18: Agent Memory – Short-Term and Long-Term State | AA18: MS Module | AB18: LP2 | AC18: M5 | AD18: Integrate Your Agent with Microsoft 365
C19: 24 | D19: 4 | E19: 3 | G19: 2 | H19: 5 | L19: Integrate Your Agent with Microsoft 365 | AA19: MS Module | AB19: LP2 | AC19: M6 | AD19: Build Agent-Driven Workflows using Microsoft Foundry
C20: 19 | D20: 3 | E20: 5 | G20: 2 | H20: 6 | I20: 13 | J20: 13 | K20: Sequential vs Concurrent Agent Execution | L20: Build Agent-Driven Workflows using Microsoft Foundry | M20: Sequential vs. Concurrent Agent Execution | AA20: MS Module | AB20: LP2 | AC20: M7 | AD20: Develop an AI Agent with Microsoft Agent Framework
C21: 20 | D21: 3 | E21: 6 | G21: 2 | H21: 7 | I21: 10 | J21: 11 | K21: Multi-Agent – Handoff Pattern | L21: Develop an AI Agent with Microsoft Agent Framework | M21: Multi-Agent Orchestration – Microsoft Agent Framework | AA21: MS Module | AB21: LP2 | AC21: M8 | AD21: Orchestrate a Multi-Agent Solution using the Microsoft Agent Framework
C22: 22 | D22: 4 | E22: 1 | G22: 2 | H22: 8 | I22: 14 | J22: 12 | K22: Multi-Agent – Manager (Magentic) Pattern | L22: Orchestrate a Multi-Agent Solution using the Microsoft Agent Framework | M22: Human-in-the-Loop (HITL) – Approval Gates | AA22: MS Module | AB22: LP2 | AC22: M9 | AD22: Discover Azure AI Agents with A2A
C23: 23 | D23: 4 | E23: 2 | G23: 2 | H23: 9 | L23: Discover Azure AI Agents with A2A | AA23: MS Learning Path | AB23: LP3 | AD23: Develop Natural Language Solutions in Azure
B24: 1 | C24: 25 | D24: 4 | E24: 4 | G24: 3 | H24: 1 | I24: 19 | J24: 18 | K24: Input Transformation – NLP Preprocessing | L24: Analyze Text with Azure Language in Foundry Tools | M24: Input Transformation – NLP Preprocessing for Agents | AA24: MS Module | AB24: LP3 | AC24: M1 | AD24: Analyze Text with Azure Language in Foundry Tools
B25: 2 | C25: 25 | D25: 4 | E25: 4 | G25: 3 | H25: 2 | I25: 19 | J25: 19 | K25: Secure Secret Management with Azure Key Vault | L25: Develop a Text Analysis Agent with the Azure Language MCP Server | M25: Input Transformation – NLP Preprocessing for Agents | AA25: MS Module | AB25: LP3 | AC25: M2 | AD25: Develop a Text Analysis Agent with the Azure Language MCP Server
B26: 1 | C26: 26 | D26: 4 | E26: 5 | G26: 3 | H26: 3 | I26: 18 | L26: Develop a Speech-Capable Generative AI Application | M26: Multimodal Integration – Vision, Speech & Document Intelligence | AA26: MS Module | AB26: LP3 | AC26: M3 | AD26: Develop a Speech-Capable Generative AI Application
B27: 2 | C27: 26 | D27: 4 | E27: 5 | G27: 3 | H27: 4 | I27: 18 | L27: Create Speech-Enabled Apps with Azure Speech in Microsoft Foundry Tools | M27: Multimodal Integration – Vision, Speech & Document Intelligence | AA27: MS Module | AB27: LP3 | AC27: M4 | AD27: Create Speech-Enabled Apps with Azure Speech in Microsoft Foundry Tools
B28: 1 | C28: 27 | D28: 4 | E28: 6 | G28: 3 | H28: 5 | L28: Develop a Speech Agent with the Azure Speech MCP Server | AA28: MS Module | AB28: LP3 | AC28: M5 | AD28: Develop a Speech Agent with the Azure Speech MCP Server
B29: 2 | C29: 27 | D29: 4 | E29: 6 | G29: 3 | H29: 6 | L29: Develop an Azure Speech Voice Live Agent in Microsoft Foundry | AA29: MS Module | AB29: LP3 | AC29: M6 | AD29: Develop an Azure Speech Voice Live Agent in Microsoft Foundry
B30: 3 | C30: 27 | D30: 4 | E30: 6 | G30: 3 | H30: 7 | L30: Translate Text and Speech with Microsoft Foundry Tools | AA30: MS Module | AB30: LP3 | AC30: M7 | AD30: Translate Text and Speech with Microsoft Foundry Tools
B31: 1 | C31: 29 | D31: 5 | E31: 1 | G31: 4 | H31: 1 | J31: 17 | K31: Multimodal Integration – Vision, Speech, Document Intelligence | L31: Develop a Vision-Enabled Generative AI Application | AA31: MS Learning Path | AB31: LP4 | AD31: Extract Insights from Visual Data on Azure
B32: 2 | C32: 29 | D32: 5 | E32: 1 | G32: 4 | H32: 2 | J32: 17 | K32: Multimodal Integration – Vision, Speech, Document Intelligence | L32: Generate Images with AI | AA32: MS Module | AB32: LP4 | AC32: M1 | AD32: Develop a Vision-Enabled Generative AI Application
B33: 1 | C33: 30 | D33: 5 | E33: 2 | G33: 4 | H33: 3 | L33: Generate Videos with Microsoft Foundry | AA33: MS Module | AB33: LP4 | AC33: M2 | AD33: Generate Images with AI
B34: 2 | C34: 30 | D34: 5 | E34: 2 | G34: 4 | H34: 4 | L34: Analyze Images with Content Understanding | AA34: MS Module | AB34: LP4 | AC34: M3 | AD34: Generate Videos with Microsoft Foundry
B35: 1 | C35: 31 | D35: 5 | E35: 3 | G35: 4 | H35: 5 | L35: Create a Multimodal Analysis Solution with Azure Content Understanding | AA35: MS Module | AB35: LP4 | AC35: M4 | AD35: Analyze Images with Content Understanding
B36: 2 | C36: 31 | D36: 5 | E36: 3 | G36: 4 | H36: 6 | L36: Create an Azure Content Understanding Client Application | AA36: MS Module | AB36: LP4 | AC36: M5 | AD36: Create a Multimodal Analysis Solution with Azure Content Understanding
C37: 32 | D37: 5 | E37: 4 | G37: 4 | H37: 7 | L37: Extract Data with Azure Document Intelligence | AA37: MS Module | AB37: LP4 | AC37: M6 | AD37: Create an Azure Content Understanding Client Application
C38: 10 | D38: 2 | E38: 3 | G38: 4 | H38: 8 | J38: 8 | K38: Azure AI Search (Part 3) – Agentic RAG | L38: Create a Knowledge Mining Solution with Azure AI Search | AA38: MS Module | AB38: LP4 | AC38: M7 | AD38: Extract Data with Azure Document Intelligence
C39: 21 | D39: 3 | E39: 7 | I39: 15 | J39: 14 | K39: OpenTelemetry Debugging | M39: Foundry Trace – OpenTelemetry Debugging | AA39: MS Module | AB39: LP4 | AC39: M8 | AD39: Create a Knowledge Mining Solution with Azure AI Search
C40: 40 | D40: 6 | E40: 5 | I40: 21 | J40: 20 | K40: Complete Agent Integration – Production-Ready System | M40: Complete Agent Solution – Integration & Exam Readiness | AA40: Udemy Concept | AB40: C1 | AD40: What Is an AI Agent?
C41: 18 | D41: 3 | E41: 4 | J41: 16 | K41: Agent Memory – Long-Term User Memory (Cosmos DB) | AA41: Udemy Concept | AB41: C2 | AD41: Unit 1 Code Walkthrough: Deploying your first Agent
...

Sheet Dashboard
A1: AI-103 6-Week Study Schedule — Updated Balanced Plan
A3: Metric | B3: Value | D3: Week | E3: MS | F3: Udemy Concepts | G3: Udemy Labs | H3: Notes/Review | I3: Total Hours | J3: Total Time
A4: Total planned time (hours) | B4: ='Weekly Summary'!H8 -> 91.166667 | D4: 1 | E4: ='Weekly Summary'!C2/60 -> 5.85 | F4: ='Weekly Summary'!D2/60 -> 3.2166667 | G4: ='Weekly Summary'!E2/60 -> 3.1666667 | H4: ='Weekly Summary'!F2/60 -> 2.7666667 | I4: ='Weekly Summary'!H2 -> 15 | J4: ='Weekly Summary'!I2 -> 15h 00m
A5: Average per week (hours) | B5: ='Weekly Summary'!H8/6 -> 15.194444 | D5: 2 | E5: ='Weekly Summary'!C3/60 -> 6.55 | F5: ='Weekly Summary'!D3/60 -> 2.3166667 | G5: ='Weekly Summary'!E3/60 -> 3.2333333 | H5: ='Weekly Summary'!F3/60 -> 2.9 | I5: ='Weekly Summary'!H3 -> 15 | J5: ='Weekly Summary'!I3 -> 15h 00m
A6: Average per day (hours) | B6: ='Weekly Summary'!H8/42 -> 2.1706349 | D6: 3 | E6: ='Weekly Summary'!C4/60 -> 6.8333333 | F6: ='Weekly Summary'!D4/60 -> 2.3166667 | G6: ='Weekly Summary'!E4/60 -> 3.4 | H6: ='Weekly Summary'!F4/60 -> 2.7 | I6: ='Weekly Summary'!H4 -> 15.25 | J6: ='Weekly Summary'!I4 -> 15h 15m
A7: Heaviest week (hours) | B7: =MAX('Weekly Summary'!H2:H7) -> 15.5 | D7: 4 | E7: ='Weekly Summary'!C5/60 -> 9.4833333 | F7: ='Weekly Summary'!D5/60 -> 1.5833333 | G7: ='Weekly Summary'!E5/60 -> 1.3666667 | H7: ='Weekly Summary'!F5/60 -> 3.0666667 | I7: ='Weekly Summary'!H5 -> 15.5 | J7: ='Weekly Summary'!I5 -> 15h 30m
A8: Lightest week (hours) | B8: =MIN('Weekly Summary'!H2:H7) -> 15 | D8: 5 | E8: ='Weekly Summary'!C6/60 -> 6.4666667 | F8: ='Weekly Summary'!D6/60 -> 0.5 | G8: ='Weekly Summary'!E6/60 -> 1.75 | H8: ='Weekly Summary'!F6/60 -> 6.6166667 | I8: ='Weekly Summary'!H6 -> 15.333333 | J8: ='Weekly Summary'!I6 -> 15h 20m
D9: 6 | E9: ='Weekly Summary'!C7/60 -> 3.6666667 | F9: ='Weekly Summary'!D7/60 -> 2.5166667 | G9: ='Weekly Summary'!E7/60 -> 2.7833333 | H9: ='Weekly Summary'!F7/60 -> 6.1166667 | I9: ='Weekly Summary'!H7 -> 15.083333 | J9: ='Weekly Summary'!I7 -> 15h 05m
A10: Coverage Check | B10: Status | D10: Category | E10: MS | F10: Udemy Concepts | G10: Udemy Labs | H10: Notes/Review | I10: Total | J10: Total Time
A11: Udemy Concepts | B11: =COUNTIF('Udemy Concept Coverage'!G2:G22,"Covered")&" / 21 covered" -> 21 / 21 covered | D11: Total Hours | E11: =SUM('Weekly Summary'!C2:C7)/60 -> 38.85 | F11: =SUM('Weekly Summary'!D2:D7)/60 -> 12.45 | G11: =SUM('Weekly Summary'!E2:E7)/60 -> 15.7 | H11: =SUM('Weekly Summary'!F2:F7)/60 -> 24.166667 | I11: =SUM('Weekly Summary'!H2:H7) -> 91.166667 | J11: =INT(SUM('Weekly Summary'!G2:G7)/60)&"h "&TEXT(MOD(SUM('Weekly Summary'!G2:G7),60),"00")&"m" -> 91h 10m
A12: Udemy Labs | B12: =COUNTIF('Udemy Lab Coverage'!G2:G21,"Covered")&" / 20 covered" -> 20 / 20 covered
A13: C15/L14 observability | B13: Added in Week 3 Day 7
A14: L17 repetition | B14: Reduced to one formal pass + one review
A15: Daily distribution | B15: Mostly 2h–2h 40m; weekly totals tightly balanced

Sheet 6-Week Schedule
A1: Week | B1: Day | C1: Focus | D1: Microsoft Learn | E1: Udemy Concepts | F1: Udemy Labs | G1: MS Time (min) | H1: Udemy Concept Time (min) | I1: Udemy Lab Time (min) | J1: Notes / Review Time (min) | K1: Total Time (min) | L1: Total Hours | M1: Total Time | N1: Coverage Type | O1: Status
A2: 1 | B2: 1 | C2: AI agent + Foundry foundation | D2: LP1 M1: Plan and Prepare | E2: C1 What Is an AI Agent; C2 Code Walkthrough; C3 Foundry Platform | F2: L1 First Agent Call | G2: 60 | H2: 78 | I2: 24 | J2: 8 | K2: =SUM(G2:J2) -> 170 | L2: =K2/60 -> 2.8333333 | M2: =INT(K2/60)&"h "&TEXT(MOD(K2,60),"00")&"m" -> 2h 50m | N2: Formal | O2: Not Started
A3: 1 | B3: 2 | C3: Responsible AI + safety | D3: LP1 M6: Responsible Generative AI | E3: C5 Responsible AI & Safety | F3: L2 Content Safety | G3: 45 | H3: 21 | I3: 36 | J3: 18 | K3: =SUM(G3:J3) -> 120 | L3: =K3/60 -> 2 | M3: =INT(K3/60)&"h "&TEXT(MOD(K3,60),"00")&"m" -> 2h 00m | N3: Formal | O3: Not Started
A4: 1 | B4: 3 | C4: Model selection | D4: LP1 M2: Select, Deploy, Evaluate Models | E4: C6 Model Selection | F4: L4 LLM vs SLM Routing | G4: 63 | H4: 21 | I4: 39 | J4: 17 | K4: =SUM(G4:J4) -> 140 | L4: =K4/60 -> 2.3333333 | M4: =INT(K4/60)&"h "&TEXT(MOD(K4,60),"00")&"m" -> 2h 20m | N4: Formal | O4: Not Started
A5: 1 | B5: 4 | C5: Evaluation and model parameters | D5: LP1 M2: evaluation review | E5: C16 Performance Evaluation | F5: L5 Model Parameters | G5: 45 | H5: 25 | I5: 37 | J5: 13 | K5: =SUM(G5:J5) -> 120 | L5: =K5/60 -> 2 | M5: =INT(K5/60)&"h "&TEXT(MOD(K5,60),"00")&"m" -> 2h 00m | N5: Formal + Review | O5: Not Started
A6: 1 | B6: 5 | C6: Chat app + context | D6: LP1 M3: Generative AI Chat App | E6: C9 Context Management | F6: L3 System Instructions | G6: 53 | H6: 19 | I6: 39 | J6: 19 | K6: =SUM(G6:J6) -> 130 | L6: =K6/60 -> 2.1666667 | M6: =INT(K6/60)&"h "&TEXT(MOD(K6,60),"00")&"m" -> 2h 10m | N6: Formal | O6: Not Started
A7: 1 | B7: 6 | C7: Prompt optimisation | D7: LP1 M5: Optimize Generative AI Performance (Part 1) | E7: C20 Programmatic Prompt Construction | F7: — | G7: 60 | H7: 14 | I7: 0 | J7: 46 | K7: =SUM(G7:J7) -> 120 | L7: =K7/60 -> 2 | M7: =INT(K7/60)&"h "&TEXT(MOD(K7,60),"00")&"m" -> 2h 00m | N7: Formal | O7: Not Started
A8: 1 | B8: 7 | C8: Weekly review + exam mapping | D8: LP1 review | E8: C1–C6, C9, C16, C20 review | F8: L1–L5 review | G8: 25 | H8: 15 | I8: 15 | J8: 45 | K8: =SUM(G8:J8) -> 100 | L8: =K8/60 -> 1.6666667 | M8: =INT(K8/60)&"h "&TEXT(MOD(K8,60),"00")&"m" -> 1h 40m | N8: Formal + Review | O8: Not Started
A9: 2 | B9: 1 | C9: Prompting / RAG start | D9: LP1 M5 Optimize: RAG section | E9: C7 Agentic RAG | F9: L6 Azure AI Search Part 1 | G9: 71 | H9: 23 | I9: 24 | J9: 22 | K9: =SUM(G9:J9) -> 140 | L9: =K9/60 -> 2.3333333 | M9: =INT(K9/60)&"h "&TEXT(MOD(K9,60),"00")&"m" -> 2h 20m | N9: Formal | O9: Not Started
A10: 2 | B10: 2 | C10: RAG grounding | D10: LP1 M5 grounding review | E10: C8 Advanced Grounding | F10: L7 Vector Search / Semantic Ranking | G10: 60 | H10: 22 | I10: 28 | J10: 20 | K10: =SUM(G10:J10) -> 130 | L10: =K10/60 -> 2.1666667 | M10: =INT(K10/60)&"h "&TEXT(MOD(K10,60),"00")&"m" -> 2h 10m | N10: Formal + Review | O10: Not Started
A11: 2 | B11: 3 | C11: Knowledge mining support | D11: LP4 M8 Azure AI Search / Knowledge Mining | E11: C7/C8 review | F11: L8 Agentic RAG | G11: 68 | H11: 20 | I11: 24 | J11: 28 | K11: =SUM(G11:J11) -> 140 | L11: =K11/60 -> 2.3333333 | M11: =INT(K11/60)&"h "&TEXT(MOD(K11,60),"00")&"m" -> 2h 20m | N11: Formal + Review | O11: Not Started
A12: 2 | B12: 4 | C12: Tool calling | D12: LP1 M4 Apps That Use Tools | E12: C11 Tool Calling | F12: L9 REST API Integration | G12: 60 | H12: 21 | I12: 44 | J12: 20 | K12: =SUM(G12:J12) -> 145 | L12: =K12/60 -> 2.4166667 | M12: =INT(K12/60)&"h "&TEXT(MOD(K12,60),"00")&"m" -> 2h 25m | N12: Formal | O12: Not Started
A13: 2 | B13: 5 | C13: Custom tools | D13: LP2 M2 Custom Tools | E13: C11 review | F13: L9 review | G13: 53 | H13: 10 | I13: 20 | J13: 37 | K13: =SUM(G13:J13) -> 120 | L13: =K13/60 -> 2 | M13: =INT(K13/60)&"h "&TEXT(MOD(K13,60),"00")&"m" -> 2h 00m | N13: Formal + Review | O13: Not Started
... A43: 6 | B43: 7 | C43: Final cheat sheet | D43: Exam traps, service-selection notes, weak areas | E43: — | F43: — | G43: 0 | H43: 0 | I43: 0 | J43: 20 | K43: =SUM(G43:J43) -> 20 | L43: =K43/60 -> 0.33333333 | M43: =INT(K43/60)&"h "&TEXT(MOD(K43,60),"00")&"m" -> 0h 20m | N43: Formal + Review | O43: Not Started

Sheet Sheet1
A1: Week | B1: Day | C1: Focus | D1: Microsoft Learn | E1: L | F1: M | G1: C | H1: L | I1: Udemy Concepts | J1: Udemy Labs | K1: MS Time (min) | L1: Udemy Concept Time (min) | M1: Udemy Lab Time (min) | N1: Notes / Review Time (min) | O1: Total Time (min) | P1: Total Time | Q1: Coverage Type | R1: Status
A2: 1 | B2: 1 | C2: AI agent + Foundry foundation | D2: LP1 M1: Plan and Prepare | E2: 1 | F2: 1 | G2: 1 | H2: 1 | I2: C1 What Is an AI Agent; C2 Code Walkthrough; C3 Foundry Platform | J2: L1 First Agent Call | K2: 60 | L2: 78 | M2: 24 | N2: 8 | O2: 170 | P2: 2h 50m | Q2: Formal | R2: Not Started
A3: 1 | B3: 3 | C3: Model selection | D3: LP1 M2: Select, Deploy, Evaluate Models | E3: 1 | F3: 2 | G3: 6 | H3: 4 | I3: C6 Model Selection | J3: L4 LLM vs SLM Routing | K3: 63 | L3: 21 | M3: 39 | N3: 17 | O3: 140 | P3: 2h 20m | Q3: Formal | R3: Not Started
A4: 1 | B4: 4 | C4: Evaluation and model parameters | D4: LP1 M2: evaluation review | E4: 1 | F4: 2 | G4: 16 | H4: 5 | I4: C16 Performance Evaluation | J4: L5 Model Parameters | K4: 45 | L4: 25 | M4: 37 | N4: 13 | O4: 120 | P4: 2h 00m | Q4: Formal + Review | R4: Not Started
A5: 1 | B5: 5 | C5: Chat app + context | D5: LP1 M3: Generative AI Chat App | E5: 1 | F5: 3 | G5: 9 | H5: 3 | I5: C9 Context Management | J5: L3 System Instructions | K5: 53 | L5: 19 | M5: 39 | N5: 19 | O5: 130 | P5: 2h 10m | Q5: Formal | R5: Not Started
A6: 2 | B6: 4 | C6: Tool calling | D6: LP1 M4 Apps That Use Tools | E6: 1 | F6: 4 | G6: 11 | H6: 9 | I6: C11 Tool Calling | J6: L9 REST API Integration | K6: 60 | L6: 21 | M6: 44 | N6: 20 | O6: 145 | P6: 2h 25m | Q6: Formal | R6: Not Started
A7: 2 | B7: 1 | C7: Prompting / RAG start | D7: LP1 M5 Optimize: RAG section | E7: 1 | F7: 5 | G7: 7 | H7: 6 | I7: C7 Agentic RAG | J7: L6 Azure AI Search Part 1 | K7: 71 | L7: 23 | M7: 24 | N7: 22 | O7: 140 | P7: 2h 20m | Q7: Formal | R7: Not Started
A8: 2 | B8: 2 | C8: RAG grounding | D8: LP1 M5 grounding review | E8: 1 | F8: 5 | G8: 8 | H8: 7 | I8: C8 Advanced Grounding | J8: L7 Vector Search / Semantic Ranking | K8: 60 | L8: 22 | M8: 28 | N8: 20 | O8: 130 | P8: 2h 10m | Q8: Formal + Review | R8: Not Started
A9: 1 | B9: 6 | C9: Prompt optimisation | D9: LP1 M5: Optimize Generative AI Performance (Part 1) | E9: 1 | F9: 5 | G9: 20 | I9: C20 Programmatic Prompt Construction | J9: — | K9: 60 | L9: 14 | M9: 0 | N9: 46 | O9: 120 | P9: 2h 00m | Q9: Formal | R9: Not Started
A10: 1 | B10: 2 | C10: Responsible AI + safety | D10: LP1 M6: Responsible Generative AI | E10: 1 | F10: 6 | G10: 5 | H10: 2 | I10: C5 Responsible AI & Safety | J10: L2 Content Safety | K10: 45 | L10: 21 | M10: 36 | N10: 18 | O10: 120 | P10: 2h 00m | Q10: Formal | R10: Not Started
A12: 3 | B12: 2 | C12: Identity and security | D12: LP2 M1 deployment/security sections | E12: 2 | F12: 1 | G12: 4 | H12: 19 | I12: C4 Entra Agent ID | J12: L19 Azure Key Vault | K12: 45 | L12: 23 | M12: 26 | N12: 26 | O12: 120 | P12: 2h 00m | Q12: Formal | R12: Not Started
A13: 3 | B13: 1 | C13: Agent foundations | D13: LP2 M1 AI Agents with Foundry + VS Code | E13: 2 | F13: 1 | I13: C1/C2 agent foundation review | J13: L1 review | K13: 95 | L13: 20 | M13: 10 | N13: 15 | O13: 140 | P13: 2h 20m | Q13: Formal + Review | R13: Not Started
A14: 2 | B14: 5 | C14: Custom tools | D14: LP2 M2 Custom Tools | E14: 2 | F14: 2 | I14: C11 review | J14: L9 review | K14: 53 | L14: 10 | M14: 20 | N14: 37 | O14: 120 | P14: 2h 00m | Q14: Formal + Review | R14: Not Started
A15: 2 | B15: 6 | C15: MCP tools | D15: LP2 M3 MCP Tools | E15: 2 | F15: 3 | G15: 12 | H15: 10 | I15: C12 MCP | J15: L10 MCP Lab | K15: 51 | L15: 28 | M15: 39 | N15: 17 | O15: 135 | P15: 2h 15m | Q15: Formal | R15: Not Started
A16: 3 | B16: 3 | C16: Knowledge agents | D16: LP2 M4 Foundry IQ | E16: 2 | F16: 4 | G16: 17 | H16: 15 | I16: C17 Agent Memory | J16: L15 Short-Term Memory | K16: 71 | L16: 21 | M16: 38 | N16: 20 | O16: 150 | P16: 2h 30m | Q16: Formal | R16: Not Started
A17: 4 | B17: 3 | C17: Microsoft 365 integration | D17: LP2 M5 M365, Teams, Copilot, Work IQ | E17: 2 | F17: 5 | I17: — | J17: — | K17: 74 | L17: 0 | M17: 0 | N17: 46 | O17: 120 | P17: 2h 00m | Q17: Formal | R17: Not Started
A18: 3 | B18: 5 | C18: Agent workflows | D18: LP2 M6 Agent Workflows | E18: 2 | F18: 6 | G18: 13 | H18: 13 | I18: C13 Sequential vs Concurrent | J18: L13 Sequential vs Concurrent | K18: 64 | L18: 19 | M18: 30 | N18: 17 | O18: 130 | P18: 2h 10m | Q18: Formal | R18: Not Started
A19: 3 | B19: 6 | C19: Agent framework + handoff | D19: LP2 M7 Agent Framework | E19: 2 | F19: 7 | G19: 10 | H19: 11 | I19: C10 Multi-Agent Orchestration | J19: L11 Handoff Pattern | K19: 55 | L19: 22 | M19: 27 | N19: 16 | O19: 120 | P19: 2h 00m | Q19: Formal | R19: Not Started
A20: 4 | B20: 1 | C20: Multi-agent orchestration | D20: LP2 M8 Multi-Agent Solution | E20: 2 | F20: 8 | G20: 14 | H20: 12 | I20: C14 HITL Approval Gates | J20: L12 Manager / Magentic Pattern | K20: 73 | L20: 22 | M20: 25 | N20: 20 | O20: 140 | P20: 2h 20m | Q20: Formal | R20: Not Started
A21: 4 | B21: 2 | C21: A2A and execution review | D21: LP2 M9 Azure AI Agents with A2A | E21: 2 | F21: 9 | I21: C13 review | J21: L13 review | K21: 56 | L21: 10 | M21: 20 | N21: 34 | O21: 120 | P21: 2h 00m | Q21: Formal + Review | R21: Not Started
A22: 4 | B22: 4 | C22: Text analysis | D22: LP3 M1–M2 Azure Language + Language MCP | E22: 3 | F22: 1,2 | G22: 19 | H22: 18,19 | I22: C19 NLP Preprocessing | J22: L18 NLP Preprocessing | K22: 98 | L22: 18 | M22: 27 | N22: 22 | O22: 165 | P22: 2h 45m | Q22: Formal | R22: Not Started
A23: 4 | B23: 5 | C23: Speech apps + multimodal concepts | D23: LP3 M3–M4 Speech-capable apps + Azure Speech | E23: 3 | F23: 3,4 | G23: 18 | I23: C18 Multimodal Integration | J23: — | K23: 96 | L23: 25 | M23: 0 | N23: 34 | O23: 155 | P23: 2h 35m | Q23: Formal | R23: Not Started
A24: 4 | B24: 6 | C24: Speech agents and translation | D24: LP3 M5–M7 Speech MCP, Voice Live, Translation | E24: 3 | F24: 5,6,7 | I24: C18 review | J24: — | K24: 152 | L24: 10 | M24: 0 | N24: 8 | O24: 170 | P24: 2h 50m | Q24: Formal + Review | R24: Not Started
A25: 5 | B25: 4 | C25: Document Intelligence | D25: LP4 M7 Document Intelligence | E25: 4 | F25: 7 | I25: — | J25: — | K25: 71 | L25: 0 | M25: 0 | N25: 49 | O25: 120 | P25: 2h 00m | Q25: Formal | R25: Not Started
A26: 2 | B26: 3 | C26: Knowledge mining support | D26: LP4 M8 Azure AI Search / Knowledge Mining | E26: 4 | F26: 8 | H26: 8 | I26: C7/C8 review | J26: L8 Agentic RAG | K26: 68 | L26: 20 | M26: 24 | N26: 28 | O26: 140 | P26: 2h 20m | Q26: Formal + Review | R26: Not Started
A27: 5 | B27: 1 | C27: Vision apps + image generation | D27: LP4 M1–M2 Vision App + Image Generation | E27: 4 | F27: 1,2 | H27: 17 | I27: C18 review | J27: L17 Multimodal Integration | K27: 76 | L27: 10 | M27: 29 | N27: 25 | O27: 140 | P27: 2h 20m | Q27: Formal + Review | R27: Not Started
A28: 5 | B28: 2 | C28: Video + image analysis | D28: LP4 M3–M4 Video + Image Analysis | E28: 4 | F28: 3,4 | I28: — | J28: — | K28: 91 | L28: 0 | M28: 0 | N28: 39 | O28: 130 | P28: 2h 10m | Q28: Formal | R28: Not Started
A29: 5 | B29: 3 | C29: Content Understanding | D29: LP4 M5–M6 Content Understanding + Client App | E29: 4 | F29: 5,6 | I29: — | J29: — | K29: 120 | L29: 0 | M29: 0 | N29: 30 | O29: 150 | P29: 2h 30m | Q29: Formal | R29: Not Started
A30: 3 | B30: 7 | C30: Observability and tracing | D30: LP2 agent review + monitoring mapping | G30: 15 | H30: 14 | I30: C15 Foundry Trace / OpenTelemetry | J30: L14 OpenTelemetry Debugging | K30: 35 | L30: 24 | M30: 40 | N30: 36 | O30: 135 | P30: 2h 15m | Q30: Formal + Review | R30: Not Started
A31: 6 | B31: 5 | C31: Final integration | D31: Weak Microsoft modules | G31: 21 | H31: 20 | I31: C21 Complete Agent Solution | J31: L20 Complete Agent Integration | K31: 30 | L31: 26 | M31: 42 | N31: 60 | O31: 158 | P31: 2h 38m | Q31: Formal + Review | R31: Not Started
A32: 3 | B32: 4 | C32: Long-term memory | D32: LP2 M4 retrieval/memory review | H32: 16 | I32: C17 review | J32: L16 Long-Term Memory | K32: 45 | L32: 10 | M32: 33 | N32: 32 | O32: 120 | P32: 2h 00m | Q32: Formal + Review | R32: Not Started
A33: 1 | B33: 7 | C33: Weekly review + exam mapping | D33: LP1 review | I33: C1–C6, C9, C16, C20 review | J33: L1–L5 review | K33: 25 | L33: 15 | M33: 15 | N33: 45 | O33: 100 | P33: 1h 40m | Q33: Formal + Review | R33: Not Started
A34: 2 | B34: 7 | C34: Weekly review + exam mapping | D34: LP1 M4–M5, LP2 M2–M3 review | I34: C7, C8, C11, C12 review | J34: L6–L10 review | K34: 30 | L34: 15 | M34: 15 | N34: 30 | O34: 90 | P34: 1h 30m | Q34: Formal + Review | R34: Not Started
A35: 4 | B35: 7 | C35: Weekly review + exam mapping | D35: LP2 / LP3 checkpoint | I35: Quick recall | J35: Quick recall | K35: 20 | L35: 10 | M35: 10 | N35: 20 | O35: 60 | P35: 1h 00m | Q35: Formal | R35: Not Started
A36: 5 | B36: 5 | C36: Knowledge mining / AI Search reinforcement | D36: LP4 M8 review / weak-area drill | I36: C7/C8 review | J36: L6–L8 review | K36: 30 | L36: 20 | M36: 76 | N36: 34 | O36: 160 | P36: 2h 40m | Q36: Formal + Review | R36: Not Started
A37: 5 | B37: 6 | C37: Study-guide mapping: vision + extraction | D37: Vision, multimodal, document extraction domains | I37: — | J37: — | K37: 0 | L37: 0 | M37: 0 | N37: 130 | O37: 130 | P37: 2h 10m | Q37: Formal | R37: Not Started
A38: 5 | B38: 7 | C38: Buffer / weak-area drill | D38: Weak Microsoft modules | I38: Optional weak concepts | J38: Optional lab repeat | K38: 0 | L38: 0 | M38: 0 | N38: 90 | O38: 90 | P38: 1h 30m | Q38: Formal + Review | R38: Not Started
A39: 6 | B39: 1 | C39: Study guide: Plan and manage | D39: Foundry, models, deployment, safety, monitoring review | I39: C3/C4/C5/C6/C15/C16 review | J39: L2/L4/L5/L14/L19 review | K39: 30 | L39: 30 | M39: 30 | N39: 60 | O39: 150 | P39: 2h 30m | Q39: Formal + Review | R39: Not Started
A40: 6 | B40: 2 | C40: Study guide: Generative AI and agents | D40: RAG, tools, MCP, agents, workflows review | I40: C7/C10/C11/C12/C17 review | J40: L6–L13, L15–L16 review | K40: 30 | L40: 45 | M40: 45 | N40: 60 | O40: 180 | P40: 3h 00m | Q40: Formal + Review | R40: Not Started
A41: 6 | B41: 3 | C41: Study guide: Vision, text, speech | D41: LP3 + LP4 weak areas | I41: C18/C19 review | J41: L17/L18 review | K41: 30 | L41: 20 | M41: 20 | N41: 50 | O41: 120 | P41: 2h 00m | Q41: Formal + Review | R41: Not Started
...

Sheet Sheet5
G1: Seq | H1: Type | I1: Code | K1: Name | L1: Time
G2: 1 | H2: MS Module | I2: LP1 M1 | J2: 1.1 | K2: Plan and Prepare to Develop AI Solutions on Azure | L2: 1h 00m | M2: 1
G3: 2 | H3: Udemy Concept | I3: C3 | J3: C3 | K3: Microsoft Foundry – The Agent Development Platform | L3: 26m | M3: 1
G4: 3 | H4: Udemy Concept | I4: C1 | J4: C1 | K4: What Is an AI Agent? | L4: 28m | M4: 1
G5: 4 | H5: Udemy Concept | I5: C2 | J5: C2 | K5: Unit 1 Code Walkthrough: Deploying your first Agent | L5: 24m | M5: 1
G6: 5 | H6: Udemy Lab | I6: L1 | J6: L1 | K6: Foundation – Your First Agent Call | L6: 24m | M6: 1
G7: 6 | H7: MS Module | I7: LP1 M6 | J7: 1.6 | K7: Implement a Responsible Generative AI Solution in Microsoft Foundry | L7: 45m
G8: 7 | H8: Udemy Concept | I8: C5 | J8: C5 | K8: Responsible AI & Safety for Agents | L8: 21m
G9: 8 | H9: Udemy Lab | I9: L2 | J9: L2 | K9: Content Safety – Input and Output Filtering | L9: 36m
G10: 9 | H10: MS Module | I10: LP1 M2 | J10: 1.2 | K10: Select Deploy and Evaluate Microsoft Foundry Models | L10: 1h 03m | M10: 1
G11: 10 | H11: Udemy Concept | I11: C6 | J11: C6 | K11: Model Selection – LLMs vs SLMs for Agent Tasks | L11: 21m
G12: 11 | H12: Udemy Lab | I12: L4 | J12: L4 | K12: Model Selection – LLM vs SLM Routing | L12: 39m
B13: C5, C6 | G13: 12 | H13: Udemy Lab | I13: L5 | J13: L5 | K13: LLM Model Parameters | L13: 37m
B14: L2, L3, L4, L5 | G14: 13 | H14: MS Module | I14: LP1 M3 | J14: 1.3 | K14: Develop a Generative AI Chat App with Microsoft Foundry | L14: 53m | M14: 1
G15: 14 | H15: Udemy Concept | I15: C9 | J15: C9 | K15: Context Management – System Instructions | L15: 19m
B16: C5 | C16: C6 | G16: 15 | H16: Udemy Concept | I16: C20 | J16: C20 | K16: System Instructions – Programmatic Prompt Construction | L16: 14m
B17: L2 | C17: L4 | G17: 16 | H17: Udemy Lab | I17: L3 | J17: L3 | K17: System Instructions – Dynamic Prompt Construction | L17: 39m
G18: 17 | H18: MS Module | I18: LP1 M5 | J18: 1.5 | K18: Optimize Generative AI Model Performance with Microsoft Foundry | L18: 2h 11m
B19: L3 | C19: System Instructions – Dynamic Prompt Construction | G19: 18 | H19: Udemy Concept | I19: C7 | J19: C7 | K19: Agentic RAG – Dynamic Retrieval for Agents | L19: 23m
B20: L5 | C20: LLM Model Parameters | G20: 19 | H20: Udemy Lab | I20: L6 | J20: L6 | K20: Azure AI Search Part 1 – Basic Search and Retrieval | L20: 24m
G21: 20 | H21: Udemy Lab | I21: L7 | J21: L7 | K21: Azure AI Search Part 2 – Vector Search and Semantic Ranking | L21: 28m
G22: 21 | H22: MS Module | I22: LP4 M8 | J22: 4.8 | K22: Create a Knowledge Mining Solution with Azure AI Search | L22: 1h 08m
G23: 22 | H23: Udemy Concept | I23: C8 | J23: C8 | K23: Advanced Grounding – Fabric and Cosmos DB | L23: 22m
G24: 23 | H24: Udemy Lab | I24: L8 | J24: L8 | K24: Azure AI Search Part 3 – Agentic RAG | L24: 24m
G25: 24 | H25: MS Module | I25: LP1 M4 | J25: 1.4 | K25: Develop Generative AI Apps That Use Tools | L25: 1h 00m
G26: 25 | H26: Udemy Concept | I26: C11 | J26: C11 | K26: Tool Calling – Connecting Agents to APIs | L26: 21m
G27: 26 | H27: Udemy Lab | I27: L9 | J27: L9 | K27: Tool Calling – REST API Integration | L27: 44m
G28: 27 | H28: MS Module | I28: LP2 M1 | J28: 2.1 | K28: Develop AI Agents with Microsoft Foundry and Visual Studio Code | L28: 1h 35m
G29: 28 | H29: MS Module | I29: LP2 M2 | J29: 2.2 | K29: Integrate Custom Tools into Your Agent | L29: 53m
G30: 29 | H30: MS Module | I30: LP2 M3 | J30: 2.3 | K30: Integrate MCP Tools with Azure AI Agents | L30: 51m
G31: 30 | H31: Udemy Concept | I31: C12 | J31: C12 | K31: Model Context Protocol MCP – Standardized Tool Connectivity | L31: 28m
G32: 31 | H32: Udemy Lab | I32: L10 | J32: L10 | K32: Model Context Protocol MCP – Standardized Tool Connectivity | L32: 39m
G33: 32 | H33: MS Module | I33: LP2 M4 | J33: 2.4 | K33: Build Knowledge-Enhanced AI Agents with Foundry IQ | L33: 1h 11m
G34: 33 | H34: Udemy Concept | I34: C17 | J34: C17 | K34: Agent Memory – Short-Term and Long-Term State | L34: 21m
G35: 34 | H35: Udemy Lab | I35: L15 | J35: L15 | K35: Agent Memory – Short-Term Session Memory Redis | L35: 38m
G36: 35 | H36: Udemy Lab | I36: L16 | J36: L16 | K36: Agent Memory – Long-Term User Memory Cosmos DB | L36: 33m
G37: 36 | H37: MS Module | I37: LP2 M6 | J37: 2.6 | K37: Build Agent-Driven Workflows using Microsoft Foundry | L37: 1h 04m
G38: 37 | H38: Udemy Concept | I38: C13 | J38: C13 | K38: Sequential vs Concurrent Agent Execution | L38: 19m
G39: 38 | H39: Udemy Concept | I39: C14 | J39: C14 | K39: Human-in-the-Loop HITL – Approval Gates | L39: 22m
G40: 39 | H40: Udemy Lab | I40: L13 | J40: L13 | K40: Sequential vs Concurrent Agent Execution | L40: 30m
...

Sheet Weekly Summary
A1: Week | B1: Focus | C1: MS Time (min) | D1: Udemy Concept Time (min) | E1: Udemy Lab Time (min) | F1: Notes / Review Time (min) | G1: Total Time (min) | H1: Total Hours | I1: Total Time
A2: 1 | B2: Foundry, agents foundation, models, chat apps | C2: =SUMIFS('6-Week Schedule'!$G:$G,'6-Week Schedule'!$A:$A,A2) -> 351 | D2: =SUMIFS('6-Week Schedule'!$H:$H,'6-Week Schedule'!$A:$A,A2) -> 193 | E2: =SUMIFS('6-Week Schedule'!$I:$I,'6-Week Schedule'!$A:$A,A2) -> 190 | F2: =SUMIFS('6-Week Schedule'!$J:$J,'6-Week Schedule'!$A:$A,A2) -> 166 | G2: =SUM(C2:F2) -> 900 | H2: =G2/60 -> 15 | I2: =INT(G2/60)&"h "&TEXT(MOD(G2,60),"00")&"m" -> 15h 00m
A3: 2 | B3: RAG, Azure AI Search, tools, MCP | C3: =SUMIFS('6-Week Schedule'!$G:$G,'6-Week Schedule'!$A:$A,A3) -> 393 | D3: =SUMIFS('6-Week Schedule'!$H:$H,'6-Week Schedule'!$A:$A,A3) -> 139 | E3: =SUMIFS('6-Week Schedule'!$I:$I,'6-Week Schedule'!$A:$A,A3) -> 194 | F3: =SUMIFS('6-Week Schedule'!$J:$J,'6-Week Schedule'!$A:$A,A3) -> 174 | G3: =SUM(C3:F3) -> 900 | H3: =G3/60 -> 15 | I3: =INT(G3/60)&"h "&TEXT(MOD(G3,60),"00")&"m" -> 15h 00m
A4: 3 | B4: Agents, identity, memory, workflows, observability | C4: =SUMIFS('6-Week Schedule'!$G:$G,'6-Week Schedule'!$A:$A,A4) -> 410 | D4: =SUMIFS('6-Week Schedule'!$H:$H,'6-Week Schedule'!$A:$A,A4) -> 139 | E4: =SUMIFS('6-Week Schedule'!$I:$I,'6-Week Schedule'!$A:$A,A4) -> 204 | F4: =SUMIFS('6-Week Schedule'!$J:$J,'6-Week Schedule'!$A:$A,A4) -> 162 | G4: =SUM(C4:F4) -> 915 | H4: =G4/60 -> 15.25 | I4: =INT(G4/60)&"h "&TEXT(MOD(G4,60),"00")&"m" -> 15h 15m
A5: 4 | B5: Multi-agent, A2A, M365, text, speech | C5: =SUMIFS('6-Week Schedule'!$G:$G,'6-Week Schedule'!$A:$A,A5) -> 569 | D5: =SUMIFS('6-Week Schedule'!$H:$H,'6-Week Schedule'!$A:$A,A5) -> 95 | E5: =SUMIFS('6-Week Schedule'!$I:$I,'6-Week Schedule'!$A:$A,A5) -> 82 | F5: =SUMIFS('6-Week Schedule'!$J:$J,'6-Week Schedule'!$A:$A,A5) -> 184 | G5: =SUM(C5:F5) -> 930 | H5: =G5/60 -> 15.5 | I5: =INT(G5/60)&"h "&TEXT(MOD(G5,60),"00")&"m" -> 15h 30m
A6: 5 | B6: Vision, Content Understanding, Document Intelligence, Search | C6: =SUMIFS('6-Week Schedule'!$G:$G,'6-Week Schedule'!$A:$A,A6) -> 388 | D6: =SUMIFS('6-Week Schedule'!$H:$H,'6-Week Schedule'!$A:$A,A6) -> 30 | E6: =SUMIFS('6-Week Schedule'!$I:$I,'6-Week Schedule'!$A:$A,A6) -> 105 | F6: =SUMIFS('6-Week Schedule'!$J:$J,'6-Week Schedule'!$A:$A,A6) -> 397 | G6: =SUM(C6:F6) -> 920 | H6: =G6/60 -> 15.333333 | I6: =INT(G6/60)&"h "&TEXT(MOD(G6,60),"00")&"m" -> 15h 20m
A7: 6 | B7: Revision, final integration, practice assessment | C7: =SUMIFS('6-Week Schedule'!$G:$G,'6-Week Schedule'!$A:$A,A7) -> 220 | D7: =SUMIFS('6-Week Schedule'!$H:$H,'6-Week Schedule'!$A:$A,A7) -> 151 | E7: =SUMIFS('6-Week Schedule'!$I:$I,'6-Week Schedule'!$A:$A,A7) -> 167 | F7: =SUMIFS('6-Week Schedule'!$J:$J,'6-Week Schedule'!$A:$A,A7) -> 367 | G7: =SUM(C7:F7) -> 905 | H7: =G7/60 -> 15.083333 | I7: =INT(G7/60)&"h "&TEXT(MOD(G7,60),"00")&"m" -> 15h 05m
A8: Total | C8: =SUM(C2:C7) -> 2331 | D8: =SUM(D2:D7) -> 747 | E8: =SUM(E2:E7) -> 942 | F8: =SUM(F2:F7) -> 1450 | G8: =SUM(G2:G7) -> 5470 | H8: =SUM(H2:H7) -> 91.166667 | I8: =INT(G8/60)&"h "&TEXT(MOD(G8,60),"00")&"m" -> 91h 10m

Sheet Udemy Concept Coverage
A1: Concept | B1: Title | C1: Duration (min) | D1: First Formal Slot | E1: Review Slot | F1: Coverage Notes | G1: Status
A2: C1 | B2: What Is an AI Agent? | C2: 28 | D2: Week 1 Day 1 | E2: Week 3 Day 1 | F2: Formal upfront foundation | G2: Covered
A3: C2 | B3: Code Walkthrough: Deploying your first Agent | C3: 24 | D3: Week 1 Day 1 | E3: Week 3 Day 1 | F3: Moved earlier; no longer review-only | G3: Covered
A4: C3 | B4: Microsoft Foundry – The Agent Development Platform | C4: 26 | D4: Week 1 Day 1 | E4: Week 6 Day 1 | F4: Foundry platform foundation | G4: Covered
A5: C4 | B5: Entra Agent ID – Agent Identity Deep Dive | C5: 23 | D5: Week 3 Day 2 | E5: Week 6 Days 1 & 4 | F5: Identity/security | G5: Covered
A6: C5 | B6: Responsible AI & Safety for Agents | C6: 21 | D6: Week 1 Day 2 | E6: Week 6 Day 1 | F6: Responsible AI | G6: Covered
A7: C6 | B7: Model Selection – LLMs vs. SLMs for Agent Tasks | C7: 21 | D7: Week 1 Day 3 | E7: Week 6 Day 1 | F7: Model selection | G7: Covered
A8: C7 | B8: Agentic RAG – Dynamic Retrieval for Agents | C8: 23 | D8: Week 2 Day 1 | E8: Week 5 Day 5; Week 6 Day 2 | F8: RAG/search | G8: Covered
A9: C8 | B9: Advanced Grounding – Fabric & Cosmos DB | C9: 22 | D9: Week 2 Day 2 | E9: Week 5 Day 5 | F9: Grounding | G9: Covered
A10: C9 | B10: Context Management – System Instructions | C10: 19 | D10: Week 1 Day 5 | E10: Week 1 Day 7 | F10: Prompt/context | G10: Covered
A11: C10 | B11: Multi-Agent Orchestration – Microsoft Agent Framework | C11: 22 | D11: Week 3 Day 6 | E11: Week 6 Day 2 | F11: Multi-agent | G11: Covered
A12: C11 | B12: Tool Calling – Connecting Agents to APIs | C12: 21 | D12: Week 2 Day 4 | E12: Week 2 Day 5; Week 6 Day 2 | F12: Tools/APIs | G12: Covered
A13: C12 | B13: Model Context Protocol (MCP) | C13: 28 | D13: Week 2 Day 6 | E13: Week 6 Day 2 | F13: MCP | G13: Covered
... A22: C21 | B22: Complete Agent Solution – Integration & Exam Readiness | C22: 26 | D22: Week 6 Day 5 | E22: — | F22: Final integration | G22: Covered

Sheet Udemy Lab Coverage
A1: Lab | B1: Title | C1: Duration (min) | D1: First Formal Slot | E1: Review Slot | F1: Coverage Notes | G1: Status
A2: L1 | B2: Foundation – Your First Agent Call | C2: 24 | D2: Week 1 Day 1 | E2: Week 1 Day 7; Week 3 Day 1 | F2: First agent call | G2: Covered
A3: L2 | B3: Content Safety - Input and Output Filtering | C3: 36 | D3: Week 1 Day 2 | E3: Week 6 Day 1 | F3: Safety filtering | G3: Covered
A4: L3 | B4: System Instructions – Dynamic Prompt Construction | C4: 39 | D4: Week 1 Day 5 | E4: Week 1 Day 7 | F4: Prompting | G4: Covered
A5: L4 | B5: Model Selection – LLM vs SLM Routing | C5: 39 | D5: Week 1 Day 3 | E5: Week 6 Day 1 | F5: Routing | G5: Covered
A6: L5 | B6: LLM Model Parameters | C6: 37 | D6: Week 1 Day 4 | E6: Week 6 Day 1 | F6: Temperature/parameters | G6: Covered
A7: L6 | B7: Azure AI Search Part 1 - Basic Search and Retrieval | C7: 24 | D7: Week 2 Day 1 | E7: Week 5 Day 5; Week 6 Day 2 | F7: Search basics | G7: Covered
A8: L7 | B8: Azure AI Search Part 2 - Vector Search and Semantic Ranking | C8: 28 | D8: Week 2 Day 2 | E8: Week 5 Day 5; Week 6 Day 2 | F8: Vector/semantic search | G8: Covered
A9: L8 | B9: Azure AI Search Part 3 - Agentic RAG | C9: 24 | D9: Week 2 Day 3 | E9: Week 5 Day 5; Week 6 Day 2 | F9: Agentic RAG | G9: Covered
A10: L9 | B10: Tool Calling – REST API Integration | C10: 44 | D10: Week 2 Day 4 | E10: Week 2 Day 5; Week 6 Day 2 | F10: Tool calling | G10: Covered
A11: L10 | B11: MCP – Standardized Tool Connectivity | C11: 39 | D11: Week 2 Day 6 | E11: Week 6 Day 2 | F11: MCP lab | G11: Covered
A12: L11 | B12: Multi-Agent - Handoff Pattern | C12: 27 | D12: Week 3 Day 6 | E12: Week 6 Day 2 | F12: Handoff | G12: Covered
A13: L12 | B13: Multi-Agent – Manager/Magentic Pattern | C13: 25 | D13: Week 4 Day 1 | E13: Week 6 Day 2 | F13: Manager pattern | G13: Covered
... A21: L20 | B21: Complete Agent Integration | C21: 42 | D21: Week 6 Day 5 | E21: — | F21: Final integration | G21: Covered

Sheet Exam Coverage Map
A1: AI-103 Exam Domain | B1: Weight | C1: Schedule Coverage | D1: Microsoft / Topic Focus | E1: Udemy Support | F1: Coverage Confidence
A2: Plan and manage an Azure AI solution | B2: 25–30% | C2: Weeks 1, 3, 6 | D2: Foundry projects, model selection, deployment, safety, monitoring, identity, cost, quotas | E2: C3, C4, C5, C6, C15, C16; L2, L4, L5, L14, L19 | F2: High
A3: Implement generative AI and agentic solutions | B3: 30–35% | C3: Weeks 1–4, 6 | D3: Chat apps, tools, RAG, MCP, agents, memory, workflows, multi-agent, HITL | E3: C1, C2, C7, C8, C9, C10, C11, C12, C13, C14, C17, C20, C21; L1, L3, L6–L13, L15–L16, L20 | F3: Very High
A4: Implement computer vision solutions | B4: 10–15% | C4: Week 5, Week 6 | D4: Vision-enabled apps, image/video analysis, generation, multimodal understanding | E4: C18; L17 | F4: Medium
A5: Implement text analysis solutions | B5: 10–15% | C5: Week 4, Week 6 | D5: Language, NLP preprocessing, speech, translation | E5: C18, C19; L18 | F5: Medium
A6: Implement information extraction solutions | B6: 10–15% | C6: Weeks 2, 5, 6 | D6: Content Understanding, Document Intelligence, OCR, AI Search, RAG ingestion | E6: C7, C8, C18; L6–L8, L17 | F6: Medium–High

Sheet Source Notes
A1: Source | B1: Used for | C1: Notes | D1: File Reference
A2: AI-103 Study Guide | B2: Exam domain weights and topic alignment | C2: Skills measured as of April 16, 2026 | D2: Pasted markdown (2)(1).md
A3: Microsoft AI-103 course syllabus | B3: Microsoft Learn module sequence and durations | C3: 29h 36m self-paced, 30 modules | D3: AI-103_Complete_Course_Syllabus(6).md
A4: Udemy AI-103 outline | B4: Concept and lab coverage | C4: 21 concepts, 20 labs, total 18h 20m | D4: Udemy(6).md
A5: Previous 6-week plan | B5: Baseline schedule | C5: Updated to fix gaps and balance load | D5: Pasted markdown(15).md
